<mujocoinclude>

<!-- =================================================
    Copyright 2018 Vikash Kumar
    Model   :: Franka (MuJoCoV2.0)
    Author  :: Vikash Kumar (vikashplus@gmail.com)
    source  :: https://github.com/vikashplus/franka_sim
    License :: Under Apache License, Version 2.0 (the "License"); you may not use this file except in compliance with the License. You may obtain a copy of the License at http://www.apache.org/licenses/LICENSE-2.0 Unless required by applicable law or agreed to in writing, software distributed under the License is distributed on an "AS IS" BASIS, WITHOUT WARRANTIES OR CONDITIONS OF ANY KIND, either express or implied. See the License for the specific language governing permissions and limitations under the License.
====================================================== -->

<!-- Robot limits pulled from https://frankaemika.github.io/docs/control_parameters.html#constants -->
        
        <body name="husky_base" pos="0 0 0" childclass="husky">
            <freejoint name="husky_base"/>
            <inertial pos="0 0 0" quat="0.707107 0 0 0.707107" mass="33.455" fullinertia="0.6022 1.7386 2.0296 -0.02364 -0.1197 -0.001544"/>
            <geom class="husky_cls" size="0.4937 0.28545 0.061875" pos="0 0 0.061875" type="box"/>
            <geom class="husky_cls" size="0.39496 0.28545 0.051875" pos="0 0 0.175625" type="box"/>
            <geom class="husky_viz" pos="0.0812 0 0.245" type="mesh" mesh="top_plate_viz" rgba="0.2 0.2 0.2 1.0"/>
            <geom class="husky_viz" pos="-0.48 0 0.091" quat="0 0 1 0" type="mesh" mesh="bumper_viz" rgba="0.2 0.2 0.2 1.0"/>
            <geom class="husky_viz" pos="0.48 0 0.091" type="mesh" mesh="bumper_viz" rgba="0.2 0.2 0.2 1.0"/>
            <geom class="husky_viz" pos="0 0 0" type="mesh" mesh="base_link_viz" rgba="0.8 0.8 0.0 1.0"/>
            <geom class="husky_viz" pos="0 0 0" type="mesh" mesh="top_chassis_viz" rgba="0.8 0.8 0.0 1.0"/>
            <site name = "husky_site"  size = "0.005" rgba = ".1 .1 .9 1" type = "sphere" />

                <body name="front_left_wheel" pos="0.256 0.2854 0.03282">
                <inertial pos="0 0 0" quat="0.707107 0 0 0.707107" mass="2.637" diaginertia="0.04411 0.02467 0.02467"/>
                <joint name="front_left_wheel" type="hinge" pos="0 0 0" axis="0 1 0"/>
                <geom class="husky_viz" pos="0 0 0" rgba="0.20313 0.20313 0.20313 1" quat="0 0 0 1" mesh="wheel_viz"/>
                <!-- <geom class="husky_cls" size="0.1651 0.1651 0.01" quat="0.707107 0.707106 0 0" type="ellipsoid"/> -->
                <geom class="husky_cls" size="0.1651 0.05715" quat="0.707107 0.707106 0 0" type="cylinder"/>
                </body>

                <body name="front_right_wheel" pos="0.256 -0.2854 0.03282">
                <inertial pos="0 0 0" quat="0.707107 0 0 0.707107" mass="2.637" diaginertia="0.04411 0.02467 0.02467"/>
                <joint name="front_right_wheel" type="hinge" pos="0 0 0" axis="0 1 0"/>
                <geom class="husky_viz" pos="0 0 0" rgba="0.20313 0.20313 0.20313 1" quat="0 0 0 1" mesh="wheel_viz"/>
                <!-- <geom class="husky_cls" size="0.1651 0.1651 0.01" quat="0.707107 0.707106 0 0" type="ellipsoid"/> -->
                <geom class="husky_cls" size="0.1651 0.05715" quat="0.707107 0.707106 0 0" type="cylinder"/>
                </body>

                <body name="rear_left_wheel" pos="-0.256 0.2854 0.03282">
                <inertial pos="0 0 0" quat="0.707107 0 0 0.707107" mass="2.637" diaginertia="0.04411 0.02467 0.02467"/>
                <joint name="rear_left_wheel" type="hinge" pos="0 0 0" axis="0 1 0"/>
                <geom class="husky_viz" pos="0 0 0" rgba="0.20313 0.20313 0.20313 1" quat="0 0 0 1" mesh="wheel_viz"/>
                <!-- <geom class="husky_cls" size="0.1651 0.1651 0.01" quat="0.707107 0.707106 0 0" type="ellipsoid"/> -->
                <geom class="husky_cls" size="0.1651 0.05715" quat="0.707107 0.707106 0 0" type="cylinder"/>
                </body>

                <body name="rear_right_wheel" pos="-0.256 -0.2854 0.03282">
                <inertial pos="0 0 0" quat="0.707107 0 0 0.707107" mass="2.637" diaginertia="0.04411 0.02467 0.02467"/>
                <joint name="rear_right_wheel" type="hinge" pos="0 0 0" axis="0 1 0" />
                <geom class="husky_viz" pos="0 0 0" rgba="0.20313 0.20313 0.20313 1" quat="0 0 1 0" mesh="wheel_viz"/>
                <!-- <geom class="husky_cls" size="0.1651 0.1651 0.01" quat="0.707107 0.707106 0 0" type="ellipsoid"/> -->
                <geom class="husky_cls" size="0.1651 0.05715" quat="0.707107 0.707106 0 0" type="cylinder"/>
                </body>

        <body name="panda0_link0" childclass="panda" pos="0.35 0 0.25" quat="1 0 0 0">
            <inertial pos="0 0 0" mass="2.91242" diaginertia="0.01 0.01 0.01"/>
            <geom class="panda_viz" mesh="link0_viz"/>
            <geom class="panda_col" mesh="link0_col" mass="2.91242"/>
                <body name="panda0_link1" pos="0 0 0.333">
                <inertial pos="0 0 0" mass="2.7063" diaginertia="0.01 0.01 0.01"/>
                <joint name="panda0_joint1" range="-2.8973 2.8973" class="panda_arm"/>
                <geom class="panda_viz" mesh="link1_viz"/>
                <geom class="panda_col" mesh="link1_col" mass="2.7063"/>
                    <body name="panda0_link2" pos="0 0 0" euler="-1.57 0 0">
                    <inertial pos="0 0 0" mass="2.73046" diaginertia="0.01 0.01 0.01"/>
                    <joint name="panda0_joint2" range="-1.7628 1.7628" class="panda_arm"/>
                    <geom class="panda_viz" mesh="link2_viz"/>
                    <geom class="panda_col" mesh="link2_col" mass="2.73046"/>
                        <body name="panda0_link3" pos="0 -0.316 0" euler="1.57 0 0">
                        <inertial pos="0 0 0" mass="2.04104" diaginertia="0.01 0.01 0.01"/>
                        <joint name="panda0_joint3" range="-2.8973 2.8973" class="panda_arm"/>
                        <geom class="panda_viz" mesh="link3_viz"/>
                        <geom class="panda_col" mesh="link3_col" mass="2.04104"/>
                            <body name="panda0_link4" pos="0.0825 0 0" euler="1.57 0 0">
                            <inertial pos="0 0 0" mass="2.08129" diaginertia="0.01 0.01 0.01"/>
                            <joint name="panda0_joint4" range="-3.0718 0.0698" class="panda_arm"/>
                            <geom class="panda_viz" mesh="link4_viz"/>
                            <geom class="panda_col" mesh="link4_col" mass="2.08129"/>
                                <body name="panda0_link5" pos="-0.0825 0.384 0" euler="-1.57 0 0">
                                <inertial pos="0 0 0" mass="3.00049" diaginertia="0.01 0.01 0.01"/>
                                <joint name="panda0_joint5" range="-2.8973 2.8973" class="panda_forearm"/>
                                <geom class="panda_viz" mesh="link5_viz"/>
                                <geom class="panda_col" mesh="link5_col" mass="3.00049"/>
                                    <body name="panda0_link6" pos="0 0 0" euler="1.57 0 1.57">
                                    <inertial pos="0 0 0" mass="1.3235" diaginertia="0.01 0.01 0.01"/>
                                    <joint name="panda0_joint6" range="-1.6573 2.1127" class="panda_forearm"/>
                                    <geom class="panda_viz" mesh="link6_viz"/>
                                    <geom class="panda_col" mesh="link6_col" mass="1.3235"/>
                                        <body name="panda0_link7" pos="0.088 0 0" euler="1.57 0 0.7854">
                                        <inertial pos="0 0 0" mass="0.2" diaginertia="0.01 0.01 0.01"/>
                                        <joint name="panda0_joint7" range="-2.8973 2.8973" axis="0 0 1" class="panda_forearm"/>
                                        <geom class="panda_viz" mesh="link7_viz"/>
                                        <geom class="panda_col" mesh="link7_col" mass="0.2"/>

                                        <!-- End Effector -->
                                        <body name="panda0_gripper">
                                            <geom pos="0 0 0.107" quat="0.92388 0 0 -0.382683" class="panda_viz" mesh="hand_viz"/>
                                            <geom pos="0 0 0.107" quat="0.92388 0 0 -0.382683" class="panda_col" mesh="hand_col" mass="0.81909"/>

                                            <body name="panda0_leftfinger" pos="0 0 0.1654" quat="0.92388 0 0 -0.382683" childclass="panda_finger">
                                                <inertial pos="-1.57863e-05 0.0118731 0.0434103" quat="0.705868 0.0310348 -0.0314925 0.706962" mass="0.0927059" diaginertia="6.57134e-05 6.09611e-05 1.09932e-05" />
                                                <joint name="panda0_finger_joint1"  axis="0 1 0" type="slide" range="0 0.04" class="panda_finger"/>
                                                <geom class="panda_viz" mesh="finger_viz"/>
                                                <geom class="panda_col" mesh="finger_col"/>
                                                <geom size="0.0185 0.0120 0.0175" pos="0 0.014 0.015" type="box" euler=".03 0 0"/>

                                                <body name = "panda0_left_fingertip" pos="0 0 0.045" euler="1.57 0 0">
                                                    <geom size = "0.009 0.001" pos = "0 0 0" euler = "0 0 0" type = "cylinder" /> 
                                                    <site name = "left_FT"  size = "0.009 0.001" rgba = ".1 .1 .9 1" type = "cylinder" />
                                                    <site name= "left_gripper" type = "box" pos="0 0 0" size="0.0185 0.0120 0.0075" euler="0 0 0"/>
                                                </body>
                                                
                                                
                                            </body>
                                            <body name="panda0_rightfinger" pos="0 0 0.1654" quat="0.92388 0 0 -0.382683"  childclass="panda_finger">
                                                <inertial pos="1.57863e-05 -0.0118731 0.0434103" quat="0.705868 -0.0310348 0.0314925 0.706962" mass="0.0927059" diaginertia="6.57134e-05 6.09611e-05 1.09932e-05" />
                                                <joint name="panda0_finger_joint2" axis="0 -1 0" type="slide" range="0 0.04" class="panda_finger"/>
                                                <geom quat="0 0 0 1" class="panda_viz" mesh="finger_viz"/>
                                                <geom quat="0 0 0 1" class="panda_col" mesh="finger_col"/>
                                                <geom size="0.0185 0.0120 0.0175" pos="0 -.014 0.015" type="box" euler="-.03 0 0"/>
                                            </body>                                            
                                        </body>
                                        </body>
                                    </body>
                                </body>
                            </body>
                        </body>
                    </body>
                </body>
            </body>
        </body>

<!-- <body name="box1">
    <inertial pos="0.905 0 0.77" mass="0.05" diaginertia = "0.0002667 0.0002667 0.0002667" />
    <freejoint name="box_joint1" />
    <geom type = "box" pos = "0.905 0 0.77" size ="0.02 0.02 0.02" friction="1.0 1.0 1.0"/>
</body>

<body name="box2">
    <inertial pos="1.0 0 0.31" mass="1" diaginertia= "0.12327 0.12327 0.12327" />
    <freejoint name="box_joint2" />
    <geom type = "box" pos = "1.0 0 0.31" size ="0.43 0.43 0.43" />
</body>  -->

</mujocoinclude>
